Workbook
Name ACT_NAME_SIGN1: 'Examens accrédités et ajouts'!$C$8
Name ACT_NAME_SIGN2: 'Examens accrédités et ajouts'!$E$8
Name ACT_PARTICIPANTS_DATE_SIGN1: 'Examens accrédités et ajouts'!$C$10
Name ACT_PARTICIPANTS_DATE_SIGN2: 'Examens accrédités et ajouts'!$E$10
Name ACT_PARTICIPANTS_SIGN1: 'Examens accrédités et ajouts'!$C$9
Name ACT_PARTICIPANTS_SIGN2: 'Examens accrédités et ajouts'!$E$9
Name P_APPLICATION_DATE: 'Examens accrédités et ajouts'!$F$2
Name P_REF: 'Examens accrédités et ajouts'!$D$2
Name P_REVISION: 'Examens accrédités et ajouts'!$E$2
Name P_REVISION_COMMENT: 'Examens accrédités et ajouts'!$A$7
Name P_TITLE: 'Examens accrédités et ajouts'!$A$4
Name P_TYPE: 'Examens accrédités et ajouts'!$B$2
Name P_UNIT: 'Examens accrédités et ajouts'!$B$3
Name Print_Area: 'FLEXI+'!$C$1:$F$584

Sheet Examens accrédités et ajouts
B1: Type | C1: Réf. Modèle | D1: Réf. Documentaire | E1: Version | F1: Appliqué(e) le
B2: 06- Liste (2 signatures) | C2: 14 | D2: 15081 | E2: 46 | F2: 19 déc. 2025
B3: Pôle Biologie Clinique
A4: Pôle Biologie Pathologie Physiologie : liste des examens accrédités et demandés à l'accréditation
A6: Description de la dernière évolution :
A7: changement PT01 et AI01
C8: Rédaction | E8: Approbation
A9: Nom(s) et fonction(s) | C9: Laure IGOUT (Gedi : Rédacteur - CHU\Pôles - Directions\Pôles Médicaux\Biologie Clinique) | E9: Adeline WAETERLOOS BARON (Gedi : Approbateur - CHU\Pôles - Directions\Pôles Médicaux\Biologie Clinique)
A10: Date | C10: 19 déc. 2025 17:20:41 | E10: 19 déc. 2025 17:21:32
A13: Pôle B2P CHU de Rouen N° accréditation 8-3081 | D13: Liste détaillée des examens accrédités
A14: Lieu de réalisation des opérations techniques (site) | B14: Service | C14: Domaine | D14: Sous-Famille | E14: Examen / analyse | F14: Nature de l'échantillon biologique (sang et dérivés, urine, selles, …) | G14: Principe de la méthode (préciser l'identification de l'équipement si méthode automatisée et le nombre ou préciser méthode manuelle, ainsi que la technique mise en oeuvre) | L14: Référence de la méthode (référence du document et version) | M14: Remarque *(ajout, changement automate, changement de méthode, changement de réactif,…) | N14: Lignes de portée | O14: Portée A/B | P14: Nombre actes réalisés en 2024
A15: HOPITAL CHARLES NICOLLE CHU ROUEN | B15: Biochimie Générale | C15: Biologie Médicale | D15: Biochimie générale et spécialisée (BIOCHBM) | E15: Créatine kinase | F15: Sang | G15: Cinétique enzymatique standardisée IFCC | H15: Quantitatif | I15: Automatisée | J15: 1 | K15: Cobas Pro Roche | L15: 10608 v4 | M15: Changement automate: mise en production le 25/9/24 | N15: BM BB01 | O15: A | P15: 23516 | Q15: =CONCATENATE(N15," _ ",O15," _ ",G15," _ ",H15," _ ",I15," _ ",J15," _ ",K15) -> BM BB01 _ A _ Cinétique enzymatique standardisée IFCC _ Quantitatif _ Automatisée _ 1 _ Cobas Pro Roche
A16: HOPITAL CHARLES NICOLLE CHU ROUEN | B16: Biochimie Générale | C16: Biologie Médicale | D16: Biochimie générale et spécialisée (BIOCHBM) | E16: Potassium | F16: Sang | G16: Potentiométrie indirecte | H16: Quantitatif | I16: Automatisée | J16: 3 | K16: Cobas Pro Roche | L16: 10674 v6 | M16: Changement automate: mise en production le 25/9/24 et 16/12/2024 | N16: BM BB01 | O16: A | P16: 321279 | Q16: =CONCATENATE(N16," _ ",O16," _ ",G16," _ ",H16," _ ",I16," _ ",J16," _ ",K16) -> BM BB01 _ A _ Potentiométrie indirecte _ Quantitatif _ Automatisée _ 3 _ Cobas Pro Roche
A17: HOPITAL CHARLES NICOLLE CHU ROUEN | B17: Biochimie Générale | C17: Biologie Médicale | D17: Biochimie générale et spécialisée (BIOCHBM) | E17: Troponine T | F17: Sang | G17: Electrochimiluminescence | H17: Quantitatif | I17: Automatisée | J17: 3 | K17: Cobas Pro Roche | L17: 10673 v6 | M17: Changement automate: mise en production le 25/9/24 et 16/12/2024 | N17: BM BB01 | O17: A | P17: 46706 | Q17: =CONCATENATE(N17," _ ",O17," _ ",G17," _ ",H17," _ ",I17," _ ",J17," _ ",K17) -> BM BB01 _ A _ Electrochimiluminescence _ Quantitatif _ Automatisée _ 3 _ Cobas Pro Roche
A18: HOPITAL CHARLES NICOLLE CHU ROUEN | B18: Biochimie Générale | C18: Biologie Médicale | D18: Biochimie générale et spécialisée (BIOCHBM) | E18: Phosphatases alcalines | F18: Sang | G18: Colorimétrie enzymatique | H18: Quantitatif | I18: Automatisée | J18: 3 | K18: Cobas Pro Roche | L18: 14978 v004 | M18: Changement automate: mise en production le 25/9/24 et 16/12/2024 | N18: BM BB01 | O18: A | P18: 148556 | Q18: =CONCATENATE(N18," _ ",O18," _ ",G18," _ ",H18," _ ",I18," _ ",J18," _ ",K18) -> BM BB01 _ A _ Colorimétrie enzymatique _ Quantitatif _ Automatisée _ 3 _ Cobas Pro Roche
A19: HOPITAL CHARLES NICOLLE CHU ROUEN | B19: Biochimie Générale | C19: Biologie Médicale | D19: Biochimie générale et spécialisée (BIOCHBM) | E19: Magnésium | F19: Sang | G19: Colorimétrie | H19: Quantitatif | I19: Automatisée | J19: 2 | K19: Cobas Pro Roche | L19: 15040 v005 | M19: Changement automate: mise en production le 25/9/24 et 16/12/2024 | N19: BM BB01 | O19: A | P19: 58673 | Q19: =CONCATENATE(N19," _ ",O19," _ ",G19," _ ",H19," _ ",I19," _ ",J19," _ ",K19) -> BM BB01 _ A _ Colorimétrie _ Quantitatif _ Automatisée _ 2 _ Cobas Pro Roche
A20: HOPITAL CHARLES NICOLLE CHU ROUEN | B20: Biochimie Générale | C20: Biologie Médicale | D20: Biochimie générale et spécialisée (BIOCHBM) | E20: Chlore | F20: Sang | G20: Potentiométrie indirecte | H20: Quantitatif | I20: Automatisée | J20: 3 | K20: Cobas Pro Roche | L20: 15038 v006 | M20: Changement automate: mise en production le 25/9/24 et 16/12/2024 | N20: BM BB01 | O20: A | P20: 319850 | Q20: =CONCATENATE(N20," _ ",O20," _ ",G20," _ ",H20," _ ",I20," _ ",J20," _ ",K20) -> BM BB01 _ A _ Potentiométrie indirecte _ Quantitatif _ Automatisée _ 3 _ Cobas Pro Roche
A21: HOPITAL CHARLES NICOLLE CHU ROUEN | B21: Biochimie Générale | C21: Biologie Médicale | D21: Biochimie générale et spécialisée (BIOCHBM) | E21: Lipase | F21: Sang | G21: Colorimétrie enzymatique | H21: Quantitatif | I21: Automatisée | J21: 2 | K21: Cobas Pro Roche | L21: 15039 v008 | M21: Changement automate: mise en production le 25/9/24 et 16/12/2024 | N21: BM BB01 | O21: A | P21: 15402 | Q21: =CONCATENATE(N21," _ ",O21," _ ",G21," _ ",H21," _ ",I21," _ ",J21," _ ",K21) -> BM BB01 _ A _ Colorimétrie enzymatique _ Quantitatif _ Automatisée _ 2 _ Cobas Pro Roche
A22: HOPITAL CHARLES NICOLLE CHU ROUEN | B22: Biochimie Générale | C22: Biologie Médicale | D22: Biochimie générale et spécialisée (BIOCHBM) | E22: Calcium | F22: Sang | G22: Colorimétrie | H22: Quantitatif | I22: Automatisée | J22: 3 | K22: Cobas Pro Roche | L22: 15026 v005 | M22: Changement automate: mise en production le 25/9/24 et 16/12/2024 | N22: BM BB01 | O22: A | P22: 112841 | Q22: =CONCATENATE(N22," _ ",O22," _ ",G22," _ ",H22," _ ",I22," _ ",J22," _ ",K22) -> BM BB01 _ A _ Colorimétrie _ Quantitatif _ Automatisée _ 3 _ Cobas Pro Roche
A23: HOPITAL CHARLES NICOLLE CHU ROUEN | B23: Biochimie Générale | C23: Biologie Médicale | D23: Biochimie générale et spécialisée (BIOCHBM) | E23: Urée | F23: Sang | G23: Méthode enzymatique (Uréase) | H23: Quantitatif | I23: Automatisée | J23: 3 | K23: Cobas Pro Roche | L23: 15075 v006 | M23: Changement automate: mise en production le 25/9/24 et 16/12/2024 | N23: BM BB01 | O23: A | P23: 313299 | Q23: =CONCATENATE(N23," _ ",O23," _ ",G23," _ ",H23," _ ",I23," _ ",J23," _ ",K23) -> BM BB01 _ A _ Méthode enzymatique (Uréase) _ Quantitatif _ Automatisée _ 3 _ Cobas Pro Roche
A24: HOPITAL CHARLES NICOLLE CHU ROUEN | B24: Biochimie Générale | C24: Biologie Médicale | D24: Biochimie générale et spécialisée (BIOCHBM) | E24: Thyréostimuline | F24: Sang | G24: Electrochimiluminescence | H24: Quantitatif | I24: Automatisée | J24: 2 | K24: Cobas pro Roche | L24: 15073 v003 | M24: Changement automate: mise en production le 25/9/24 | N24: BM BB01 | O24: A | P24: 35798 | Q24: =CONCATENATE(N24," _ ",O24," _ ",G24," _ ",H24," _ ",I24," _ ",J24," _ ",K24) -> BM BB01 _ A _ Electrochimiluminescence _ Quantitatif _ Automatisée _ 2 _ Cobas pro Roche
A25: HOPITAL CHARLES NICOLLE CHU ROUEN | B25: Biochimie Générale | C25: Biologie Médicale | D25: Biochimie générale et spécialisée (BIOCHBM) | E25: Sodium | F25: Sang | G25: Potentiométrie indirecte | H25: Quantitatif | I25: Automatisée | J25: 3 | K25: Cobas Pro Roche | L25: 15067 v006 | M25: Changement automate: mise en production le 25/9/24 et 16/12/2024 | N25: BM BB01 | O25: A | P25: 321491 | Q25: =CONCATENATE(N25," _ ",O25," _ ",G25," _ ",H25," _ ",I25," _ ",J25," _ ",K25) -> BM BB01 _ A _ Potentiométrie indirecte _ Quantitatif _ Automatisée _ 3 _ Cobas Pro Roche
A26: HOPITAL CHARLES NICOLLE CHU ROUEN | B26: Biochimie Générale | C26: Biologie Médicale | D26: Biochimie générale et spécialisée (BIOCHBM) | E26: Protides | F26: Sang | G26: Colorimétrique (Biuret) | H26: Quantitatif | I26: Automatisée | J26: 3 | K26: Cobas Pro Roche | L26: 15030 v007 | M26: Changement automate: mise en production le 25/9/24 et 16/12/2024 | N26: BM BB01 | O26: A | P26: 318697 | Q26: =CONCATENATE(N26," _ ",O26," _ ",G26," _ ",H26," _ ",I26," _ ",J26," _ ",K26) -> BM BB01 _ A _ Colorimétrique (Biuret) _ Quantitatif _ Automatisée _ 3 _ Cobas Pro Roche
... A40: HOPITAL CHARLES NICOLLE CHU ROUEN | B40: Biochimie Générale | C40: Biologie médicale | D40: Biochimie générale et spécialisée (BIOCHBM) | E40: Créatinine plasmatique | F40: Sang | G40: Colorimétrie ou colorimétrie enzymatique | H40: Quantitatif | I40: Automatisée | J40: 3 | K40: Cobas Pro Roche | L40: 24671 v3 | M40: Changement automate: mise en production le 25/9/24 et 16/12/2024 | N40: BM BB01 | O40: A | P40: 316816 | Q40: =CONCATENATE(N40," _ ",O40," _ ",G40," _ ",H40," _ ",I40," _ ",J40," _ ",K40) -> BM BB01 _ A _ Colorimétrie ou colorimétrie enzymatique _ Quantitatif _ Automatisée _ 3 _ Cobas Pro Roche
A41: HOPITAL CHARLES NICOLLE CHU ROUEN | B41: Biochimie Générale | C41: Biologie médicale | D41: Biochimie générale et spécialisée (BIOCHBM) | E41: DFG : MDRD et CKD-EPI | F41: Sang | G41: Calcul | H41: Quantitatif | I41: Automatisée | J41: NA | K41: NA | L41: 24671 v3 | N41: BM BB01 | O41: A | P41: 0 (Calcul) | Q41: =CONCATENATE(N41," _ ",O41," _ ",G41," _ ",H41," _ ",I41," _ ",J41," _ ",K41) -> BM BB01 _ A _ Calcul _ Quantitatif _ Automatisée _ NA _ NA
A42: HOPITAL CHARLES NICOLLE CHU ROUEN | B42: Biochimie Générale | C42: Biologie médicale | D42: Biochimie générale et spécialisée (BIOCHBM) | E42: Clairance à la créatinine (Cockroft) | F42: Sang | G42: Calcul | H42: Quantitatif | I42: Automatisée | J42: NA | K42: NA | L42: 24671 v3 | N42: BM BB01 | O42: A | P42: 0 (Calcul) | Q42: =CONCATENATE(N42," _ ",O42," _ ",G42," _ ",H42," _ ",I42," _ ",J42," _ ",K42) -> BM BB01 _ A _ Calcul _ Quantitatif _ Automatisée _ NA _ NA
A43: HOPITAL CHARLES NICOLLE CHU ROUEN | B43: Biochimie Générale | C43: Biologie médicale | D43: Biochimie générale et spécialisée (BIOCHBM) | E43: Bicarbonates plasmatiques | F43: Sang | G43: Méthode enzymatique (PEPCK) | H43: Quantitatif | I43: Automatisée | J43: 3 | K43: Cobas Pro Roche | L43: 26347 v1 | M43: Changement automate: mise en production le 25/9/24 et 16/12/2024 | N43: BM BB01 | O43: A | P43: 318110 | Q43: =CONCATENATE(N43," _ ",O43," _ ",G43," _ ",H43," _ ",I43," _ ",J43," _ ",K43) -> BM BB01 _ A _ Méthode enzymatique (PEPCK) _ Quantitatif _ Automatisée _ 3 _ Cobas Pro Roche
A44: HOPITAL CHARLES NICOLLE CHU ROUEN | B44: Biochimie Générale | C44: Biologie médicale | D44: Biochimie générale et spécialisée (BIOCHBM) | E44: Acide urique plasmatique | F44: Sang | G44: Colorimétrie enzymatique | H44: Quantitatif | I44: Automatisée | J44: 2 | K44: Cobas Pro Roche | L44: 26271 v2 | M44: Changement automate: mise en production le 25/9/24 et 16/12/2024 | N44: BM BB01 | O44: A | P44: 14510 | Q44: =CONCATENATE(N44," _ ",O44," _ ",G44," _ ",H44," _ ",I44," _ ",J44," _ ",K44) -> BM BB01 _ A _ Colorimétrie enzymatique _ Quantitatif _ Automatisée _ 2 _ Cobas Pro Roche
A45: HOPITAL CHARLES NICOLLE CHU ROUEN | B45: Biochimie Générale | C45: Biologie médicale | D45: Biochimie générale et spécialisée (BIOCHBM) | E45: Phosphore plasmatique | F45: Sang | G45: Spectrophotométrie UV (Molybdate d'ammonium) | H45: Quantitatif | I45: Automatisée | J45: 3 | K45: Cobas Pro Roche | L45: 26256 v3 | M45: Changement automate: mise en production le 25/9/24 et 16/12/2024 | N45: BM BB01 | O45: A | P45: 103603 | Q45: =CONCATENATE(N45," _ ",O45," _ ",G45," _ ",H45," _ ",I45," _ ",J45," _ ",K45) -> BM BB01 _ A _ Spectrophotométrie UV (Molybdate d'ammonium) _ Quantitatif _ Automatisée _ 3 _ Cobas Pro Roche
A46: HOPITAL CHARLES NICOLLE CHU ROUEN | B46: Biochimie Générale | C46: Biologie médicale | D46: Biochimie générale et spécialisée (BIOCHBM) | E46: Glucose plasmatique | F46: Sang | G46: Enzymatique | H46: Quantitatif | I46: Automatisée | J46: 3 | K46: Cobas Pro Roche | L46: 26931 v3 | M46: Changement automate: mise en production le 25/9/24 et 16/12/2024 | N46: BM BB01 | O46: A | P46: 233169 | Q46: =CONCATENATE(N46," _ ",O46," _ ",G46," _ ",H46," _ ",I46," _ ",J46," _ ",K46) -> BM BB01 _ A _ Enzymatique _ Quantitatif _ Automatisée _ 3 _ Cobas Pro Roche
A47: HOPITAL CHARLES NICOLLE CHU ROUEN | B47: Biochimie Générale | C47: Biologie médicale | D47: Biochimie générale et spécialisée (BIOCHBM) | E47: pH (Gaz du sang) | F47: Sang | G47: Potentiométrie directe | H47: Quantitatif | I47: Automatisée | J47: 4 | K47: GEM 5000 (WERFEN) | L47: 39150 v1 39370 v1 39494 v1 39889 v1 | N47: BM BB01 | O47: A | P47: 61910 | Q47: =CONCATENATE(N47," _ ",O47," _ ",G47," _ ",H47," _ ",I47," _ ",J47," _ ",K47) -> BM BB01 _ A _ Potentiométrie directe _ Quantitatif _ Automatisée _ 4 _ GEM 5000 (WERFEN)
A48: HOPITAL CHARLES NICOLLE CHU ROUEN | B48: Biochimie Générale | C48: Biologie médicale | D48: Biochimie générale et spécialisée (BIOCHBM) | E48: pO2 (Gaz du sang) | F48: Sang | G48: Potentiométrie directe | H48: Quantitatif | I48: Automatisée | J48: 4 | K48: GEM 5000 (WERFEN) | L48: 39150 v1 39370 v1 39494 v1 39889 v1 | N48: BM BB01 | O48: A | P48: voir PH | Q48: =CONCATENATE(N48," _ ",O48," _ ",G48," _ ",H48," _ ",I48," _ ",J48," _ ",K48) -> BM BB01 _ A _ Potentiométrie directe _ Quantitatif _ Automatisée _ 4 _ GEM 5000 (WERFEN)
A49: HOPITAL CHARLES NICOLLE CHU ROUEN | B49: Biochimie Générale | C49: Biologie médicale | D49: Biochimie générale et spécialisée (BIOCHBM) | E49: pCO2 (Gaz du sang) | F49: Sang | G49: Potentiométrie directe | H49: Quantitatif | I49: Automatisée | J49: 4 | K49: GEM 5000 (WERFEN) | L49: 39150 v1 39370 v1 39494 v1 39889 v1 | N49: BM BB01 | O49: A | P49: voir PH | Q49: =CONCATENATE(N49," _ ",O49," _ ",G49," _ ",H49," _ ",I49," _ ",J49," _ ",K49) -> BM BB01 _ A _ Potentiométrie directe _ Quantitatif _ Automatisée _ 4 _ GEM 5000 (WERFEN)
A50: HOPITAL CHARLES NICOLLE CHU ROUEN | B50: Biochimie Générale | C50: Biologie Médicale | D50: Biochimie générale et spécialisée (BIOCHBM) | E50: Hémogobine Totale (Gaz du sang) | F50: Sang | G50: Absorbance optique | H50: Quantitatif | I50: Automatisée | J50: 4 | K50: GEM 5000 (WERFEN) | L50: 39150 v1 39370 v1 39494 v1 39889 v1 | N50: BM BB01 | O50: A | P50: voir PH (gaz du sang) | Q50: =CONCATENATE(N50," _ ",O50," _ ",G50," _ ",H50," _ ",I50," _ ",J50," _ ",K50) -> BM BB01 _ A _ Absorbance optique _ Quantitatif _ Automatisée _ 4 _ GEM 5000 (WERFEN)
A51: HOPITAL CHARLES NICOLLE CHU ROUEN | B51: Biochimie Générale | C51: Biologie Médicale | D51: Biochimie générale et spécialisée (BIOCHBM) | E51: Carboxyhémoglobine (Gaz du sang) | F51: Sang | G51: Absorbance optique | H51: Quantitatif | I51: Automatisée | J51: 4 | K51: GEM 5000 (WERFEN) | L51: 39150 v1 39370 v1 39494 v1 39889 v1 | N51: BM BB01 | O51: A | P51: 118 | Q51: =CONCATENATE(N51," _ ",O51," _ ",G51," _ ",H51," _ ",I51," _ ",J51," _ ",K51) -> BM BB01 _ A _ Absorbance optique _ Quantitatif _ Automatisée _ 4 _ GEM 5000 (WERFEN)
A52: HOPITAL CHARLES NICOLLE CHU ROUEN | B52: Biochimie Générale | C52: Biologie Médicale | D52: Biochimie générale et spécialisée (BIOCHBM) | E52: Oxyhémoglobine (Gaz du sang) | F52: Sang | G52: Absorbance optique | H52: Quantitatif | I52: Automatisée | J52: 4 | K52: GEM 5000 (WERFEN) | L52: 39150 v1 39370 v1 39494 v1 39889 v1 | N52: BM BB01 | O52: A | P52: voir PH (gaz du sang) | Q52: =CONCATENATE(N52," _ ",O52," _ ",G52," _ ",H52," _ ",I52," _ ",J52," _ ",K52) -> BM BB01 _ A _ Absorbance optique _ Quantitatif _ Automatisée _ 4 _ GEM 5000 (WERFEN)
A53: HOPITAL CHARLES NICOLLE CHU ROUEN | B53: Biochimie Générale | C53: Biologie Médicale | D53: Biochimie générale et spécialisée (BIOCHBM) | E53: Méthémoglobine (Gaz du sang) | F53: Sang | G53: Absorbance optique | H53: Quantitatif | I53: Automatisée | J53: 4 | K53: GEM 5000 (WERFEN) | L53: 39150 v1 39370 v1 39494 v1 39889 v1 | N53: BM BB01 | O53: A | P53: 270 | Q53: =CONCATENATE(N53," _ ",O53," _ ",G53," _ ",H53," _ ",I53," _ ",J53," _ ",K53) -> BM BB01 _ A _ Absorbance optique _ Quantitatif _ Automatisée _ 4 _ GEM 5000 (WERFEN)
A54: HOPITAL CHARLES NICOLLE CHU ROUEN | B54: Hématologie | C54: Biologie Médicale | D54: Hémostase (COAGBM) | E54: Temps de Quick | F54: Plasma | G54: Chronométrique | H54: Quantitatif | I54: Automatisée | J54: 2 | K54: STAR Max3 Diagnostica STAGO (chu) | L54: 10646 v8 | M54: Nouveaux automates STARMAX3 à partir du 12/11/2024 | N54: BM CB02 | O54: A | P54: 116063 | Q54: =CONCATENATE(N54," _ ",O54," _ ",G54," _ ",H54," _ ",I54," _ ",J54," _ ",K54) -> BM CB02 _ A _ Chronométrique _ Quantitatif _ Automatisée _ 2 _ STAR Max3 Diagnostica STAGO (chu)
A55: HOPITAL CHARLES NICOLLE CHU ROUEN | B55: Hématologie | C55: Biologie Médicale | D55: Hémostase (COAGBM) | E55: Temps de céphaline + activateur | F55: Plasma | G55: Chronométrie | H55: Quantitatif | I55: Automatisée | J55: 2 | K55: STAR Max3 Diagnostica STAGO (chu) | L55: 14898 v4 | M55: Nouveaux automates STARMAX3 à partir du 12/11/2024 | N55: BM CB02 | O55: A | P55: 108233 | Q55: =CONCATENATE(N55," _ ",O55," _ ",G55," _ ",H55," _ ",I55," _ ",J55," _ ",K55) -> BM CB02 _ A _ Chronométrie _ Quantitatif _ Automatisée _ 2 _ STAR Max3 Diagnostica STAGO (chu)
A56: HOPITAL CHARLES NICOLLE CHU ROUEN | B56: Hématologie | C56: Biologie Médicale | D56: Hémostase (COAGBM) | E56: Fibrinogène | F56: Plasma | G56: Chronométrie | H56: Quantitatif | I56: Automatisée | J56: 2 | K56: STAR Max3 Diagnostica STAGO (chu) | L56: 14899 v5 | M56: Nouveaux automates STARMAX3 à partir du 12/11/2024 | N56: BM CB02 | O56: A | P56: 25228 | Q56: =CONCATENATE(N56," _ ",O56," _ ",G56," _ ",H56," _ ",I56," _ ",J56," _ ",K56) -> BM CB02 _ A _ Chronométrie _ Quantitatif _ Automatisée _ 2 _ STAR Max3 Diagnostica STAGO (chu)
...

Sheet Extensions demandées juin 2019
A1: Pôle B2P CHU de Rouen (8-3081) | C1: Liste détaillée des examens/analyses demandés à l'accréditation (réf 15081)
A2: Lieu de réalisation des opérations techniques (site) | B2: Service | C2: Domaine | D2: Sous-Famille | E2: Examen / analyse | F2: Nature de l'échantillon biologique (sang et dérivés, urine, selles, …) | G2: Principe de la méthode (préciser l'identification de l'équipement si méthode automatisée et le nombre ou préciser méthode manuelle, ainsi que la technique mise en oeuvre) | L2: Référence de la méthode (référence du document et version) | M2: Remarque(ajout, changement automate, changement de méthode, changement de réactif,…) | N2: Lignes de portée | O2: portée A/B | P2: Nombre actes réalisés en 2023
A3: HOPITAL CHARLES NICOLLE CHU ROUEN | B3: Anatomie et cytologie pathologiques | C3: Anatomie et cytologie pathologiques | D3: Génétique somatique (GENSOBM) | E3: Séquençage à Haut débit et traitement bioinformatique | F3: Acides nucléiques : ADNg ARN | G3: Détection de variants d'intérêt théranostique ou diagnostique pour les tumeurs solides par approche amplicons, séquençage parallèle massif (MiSeq Illumina) et analyse bioinformatique interne à partir d'un logiciel fournisseur | H3: qualitatif | I3: manuelle | J3: 2 | K3: séquenceur massif parallèle : MiSeq Illumina | L3: 41131 v1 41132 v1 | M3: Changement de méthode | N3: AC GS02 | O3: B | P3: 548 | Q3: =CONCATENATE(N3," _ ",O3," _ ",G3," _ ",H3," _ ",I3," _ ",J3," _ ",K3) -> AC GS02 _ B _ Détection de variants d'intérêt théranostique ou diagnostique pour les tumeurs solides par approche amplicons, séquençage parallèle massif (MiSeq Illumina) et analyse bioinformatique interne à partir d'un logiciel fournisseur _ qualitatif _ manuelle _ 2 _ séquenceur massif parallèle : MiSeq Illumina
A4: HOPITAL CHARLES NICOLLE CHU ROUEN | B4: Biologie de la Reproduction | C4: Biologie Médicale | D4: Activités Biologiques d'AMP (AMPBIOBM) | E4: Recherche et identification des spermatozoïdes, volume, mobilité, concentration | F4: Sperme Tissu testiculaire | G4: * Sperme éjaculé frais : Les spermatozoïdes sont obtenus par centrifugation et migration sur gradient de macromolécules et lavage. La mobilité des spermatozoïdes est estimée par observation au microscope. La numération des spermatozoïdes est réalisée à partir d'un hémocytomètre (cellule de Thoma) * Spermatozoïdes congelés – décongelés : Les spermatozoïdes sont obtenus par centrifugation et migration sur gradient de macromolécules et lavage. La mobilité des spermatozoïdes est estimée par observation au microscope. La numération des spermatozoïdes est réalisée à partir d'un hémocytomètre (cellule de Thoma) * Spermatozoïdes testiculaires : Les spermatozoïdes sont obtenus par dilacération mécanique du tissu testiculaire | H4: Qualitatif et Quantitatif | I4: manuelle | L4: 30339 v1 | M4: nb actes hors 415 tentatives AMP comptabilisées ci-dessous | N4: BM AP1 | O4: A | P4: 830 | Q4: =CONCATENATE(N4," _ ",O4," _ ",G4," _ ",H4," _ ",I4," _ ",J4," _ ",K4) -> BM AP1 _ A _ * Sperme éjaculé frais : Les spermatozoïdes sont obtenus par centrifugation et migration sur gradient de macromolécules et lavage. La mobilité des spermatozoïdes est estimée par observation au microscope. La numération des spermatozoïdes est réalisée à partir d'un hémocytomètre (cellule de Thoma) * Spermatozoïdes congelés – décongelés : Les spermatozoïdes sont obtenus par centrifugation et migration sur gradient de macromolécules et lavage. La mobilité des spermatozoïdes est estimée par observation au microscope. La numération des spermatozoïdes est réalisée à partir d'un hémocytomètre (cellule de Thoma) * Spermatozoïdes testiculaires : Les spermatozoïdes sont obtenus par dilacération mécanique du tissu testiculaire _ Qualitatif et Quantitatif _ manuelle _ _
A5: HOPITAL CHARLES NICOLLE CHU ROUEN | B5: Biologie de la Reproduction | C5: Biologie Médicale | D5: Activités Biologiques d'AMP (AMPBIOBM) | E5: Identification de l'ovocyte, du zygote et de l’embryon (pronuclei, globules polaires, blastomères et fragments anucléés…) | F5: Ovocyte, zygote, embryon | G5: * Recueil des gamètes et mise fécondation * Culture embryonnaire * Congélation et décongélation des ovocytes et des embryons | H5: Qualitatif | I5: manuelle | L5: 16827 v2 | N5: BM AP3 | O5: A | P5: 1147 | Q5: =CONCATENATE(N5," _ ",O5," _ ",G5," _ ",H5," _ ",I5," _ ",J5," _ ",K5) -> BM AP3 _ A _ * Recueil des gamètes et mise fécondation * Culture embryonnaire * Congélation et décongélation des ovocytes et des embryons _ Qualitatif _ manuelle _ _
O7: total actes demandé | P7: =SUM(P3:P5) -> 2525
O9: % activité demandée | P9: 0.0051597318
O11: cumul accrédité+ demandé | P11: 0.98741588

Sheet Extensions demandées oct 2021
A1: Pôle B2P CHU de Rouen (8-3081) | C1: Liste détaillée des examens/analyses demandés à l'accréditation (réf 15081)
A2: Lieu de réalisation des opérations techniques (site) | B2: Service | C2: Domaine | D2: Sous-Famille | E2: Examen / analyse | F2: Nature de l'échantillon biologique (sang et dérivés, urine, selles, …) | G2: Principe de la méthode (préciser l'identification de l'équipement si méthode automatisée et le nombre ou préciser méthode manuelle, ainsi que la technique mise en oeuvre) | L2: Référence de la méthode (référence du document et version) | M2: Remarque(ajout, changement automate, changement de méthode, changement de réactif,…) | N2: Lignes de portée | O2: portée A/B | P2: Nombre actes réalisés en 2023
A3: HOPITAL CHARLES NICOLLE CHU ROUEN | B3: Anatomie et cytologie pathologiques | C3: Anatomie et cytologie pathologiques | D3: Cytologie (CYTOACP) | E3: Examen cytologique – Observation morphologique de constituants cellulaires | F3: Prélèvement(s) cellulaire(s) d'origine humaine, en milieu liquide : frottis cervico-utérin | G3: Coloration Papanicolaou sur FCU | H3: Qualitatif | I3: Automatisée | J3: 2 | K3: Tissue-Tek Prisma Plus ThinPrep 2000 Hologic | L3: 35459 v1 | N3: AC CA01 | O3: B | P3: 1061 | Q3: =CONCATENATE(N3," _ ",O3," _ ",G3," _ ",H3," _ ",I3," _ ",J3," _ ",K3) -> AC CA01 _ B _ Coloration Papanicolaou sur FCU _ Qualitatif _ Automatisée _ 2 _ Tissue-Tek Prisma Plus ThinPrep 2000 Hologic
A4: HOPITAL CHARLES NICOLLE CHU ROUEN | B4: Immunologie | C4: Biologie Médicale | D4: Immunologie cellulaire (ICELHISTOBM) | E4: ELISPOT IFN gamma | F4: sang | G4: ELISPOT | H4: qualitatif | I4: manuelle | J4: 1 lecteur ELISPOT pour capture d'images et comptage des spots | K4: iSpot Spectrum Eurobio Scientific | L4: 35799 v1 | N4: BM IC06 | O4: B | P4: 2848 | Q4: =CONCATENATE(N4," _ ",O4," _ ",G4," _ ",H4," _ ",I4," _ ",J4," _ ",K4) -> BM IC06 _ B _ ELISPOT _ qualitatif _ manuelle _ 1 lecteur ELISPOT pour capture d'images et comptage des spots _ iSpot Spectrum Eurobio Scientific
A5: HOPITAL CHARLES NICOLLE CHU ROUEN | B5: Virologie | C5: Biologie Médicale | D5: Microbiologie Générale (MICROBIOBM) | E5: Séquençage NGS COVID-19 | F5: Ecouvillonage nasal profond, LBA | G5: Séquençage à Haut débit et Traitement bioinformatique | H5: qualitatif | I5: automatisé | J5: 1 | K5: MinIon | L5: 35598 v1 et 35804 v1 | N5: BM MG6 | O5: B | P5: 2290 | Q5: =CONCATENATE(N5," _ ",O5," _ ",G5," _ ",H5," _ ",I5," _ ",J5," _ ",K5) -> BM MG6 _ B _ Séquençage à Haut débit et Traitement bioinformatique _ qualitatif _ automatisé _ 1 _ MinIon
O8: total actes demandé (hors bio déloc) | P8: =SUM(P3:P4,P5:P5) -> 6199
O10: % activité demandée | P10: 0.0011510333
O12: cumul accrédité+ demandé | P12: 0.98856691

Sheet Extensions demandées 2024
A1: Pôle B2P CHU de Rouen (8-3081) | C1: Liste détaillée des examens/analyses demandés à l'accréditation (réf 15081)
A2: Lieu de réalisation des opérations techniques (site) | B2: Service | C2: Domaine | D2: Sous-Famille | E2: Examen / analyse | F2: Nature de l'échantillon biologique (sang et dérivés, urine, selles, …) | G2: Principe de la méthode (préciser l'identification de l'équipement si méthode automatisée et le nombre ou préciser méthode manuelle, ainsi que la technique mise en oeuvre) | L2: Référence de la méthode (référence du document et version) | M2: Remarque(ajout, changement automate, changement de méthode, changement de réactif,…) | N2: Lignes de portée | O2: portée A/B | P2: Nombre actes réalisés en 2023
A3: HOPITAL CHARLES NICOLLE CHU ROUEN | B3: Centres de prélèvement Consultation hématologie Biologie de la reproduction | C3: Biologie Médicale | D3: NA | E3: NA | F3: Sang | G3: Prélèvement par ponction veineuse directe | L3: Viskali Protocole institutionnel de prélèvement veineux périphérique (Gedi 1161) | M3: extension demandée en novembre 2024 | N3: BM PP01 | O3: NA | P3: NA | Q3: =CONCATENATE(N3," _ ",O3," _ ",G3," _ ",H3," _ ",I3," _ ",J3," _ ",K3) -> BM PP01 _ NA _ Prélèvement par ponction veineuse directe _ _ _ _
A4: HOPITAL CHARLES NICOLLE CHU ROUEN | B4: Centres de prélèvement | C4: Biologie Médicale | D4: NA | E4: NA | F4: Sang | G4: Prélèvement par ponction artérielle | L4: Viskali Protocole institutionnel de ponction artérielle | M4: extension demandée en novembre 2024 | N4: BM PP01 | O4: NA | P4: NA | Q4: =CONCATENATE(N4," _ ",O4," _ ",G4," _ ",H4," _ ",I4," _ ",J4," _ ",K4) -> BM PP01 _ NA _ Prélèvement par ponction artérielle _ _ _ _
A5: HOPITAL CHARLES NICOLLE CHU ROUEN | B5: Centres de prélèvement | C5: Biologie Médicale | D5: NA | E5: NA | F5: Urines | G5: Prélèvement par pose d’une poche pédiatrique | L5: Viskali | M5: extension demandée en novembre 2024 | N5: BM PP01 | O5: NA | P5: NA | Q5: =CONCATENATE(N5," _ ",O5," _ ",G5," _ ",H5," _ ",I5," _ ",J5," _ ",K5) -> BM PP01 _ NA _ Prélèvement par pose d’une poche pédiatrique _ _ _ _
A6: HOPITAL CHARLES NICOLLE CHU ROUEN | B6: Centres de prélèvement Biologie de la reproduction | C6: Biologie Médicale | D6: NA | E6: NA | F6: Urines | G6: Recueil des urines Prélèvement par recueil sur le site de prélèvement de poche. | L6: Viskali Protocole institutionnel de recueil des urines en vue d’un ECBU et autres examens de biologie chez un patient non sondé (Gedi 6868) Protocole institutionnel de recueil des urines chez un patient porteur d’une sonde vésicale (Gedi 245) | M6: extension demandée en novembre 2024 | N6: BM PP01 | O6: NA | P6: NA | Q6: =CONCATENATE(N6," _ ",O6," _ ",G6," _ ",H6," _ ",I6," _ ",J6," _ ",K6) -> BM PP01 _ NA _ Recueil des urines Prélèvement par recueil sur le site de prélèvement de poche. _ _ _ _
A7: HOPITAL CHARLES NICOLLE CHU ROUEN | B7: Centres de prélèvement | C7: Biologie Médicale | D7: NA | E7: NA | F7: Salive | G7: Ecouvillonnage Recueil salivaire sur buvard | L7: Viskali | M7: extension demandée en novembre 2024 | N7: BM PP01 | O7: NA | P7: NA | Q7: =CONCATENATE(N7," _ ",O7," _ ",G7," _ ",H7," _ ",I7," _ ",J7," _ ",K7) -> BM PP01 _ NA _ Ecouvillonnage Recueil salivaire sur buvard _ _ _ _
A8: HOPITAL CHARLES NICOLLE CHU ROUEN | B8: Centres de prélèvement | C8: Biologie Médicale | D8: NA | E8: NA | F8: Crachats | G8: Recueil du crachat | L8: Viskali | M8: extension demandée en novembre 2024 | N8: BM PP01 | O8: NA | P8: NA | Q8: =CONCATENATE(N8," _ ",O8," _ ",G8," _ ",H8," _ ",I8," _ ",J8," _ ",K8) -> BM PP01 _ NA _ Recueil du crachat _ _ _ _
A9: HOPITAL CHARLES NICOLLE CHU ROUEN | B9: Centres de prélèvement | C9: Biologie Médicale | D9: NA | E9: NA | F9: Selles | G9: Recueil des selles | L9: Viskali Microbiologie : Prélèvements effectués à l'unité de prélèvement (UP) (GEDI 3706) | M9: extension demandée en novembre 2024 | N9: BM PP01 | O9: NA | P9: NA | Q9: =CONCATENATE(N9," _ ",O9," _ ",G9," _ ",H9," _ ",I9," _ ",J9," _ ",K9) -> BM PP01 _ NA _ Recueil des selles _ _ _ _
A10: HOPITAL CHARLES NICOLLE CHU ROUEN | B10: Centres de prélèvement Biologie de la reproduction | C10: Biologie Médicale | D10: NA | E10: NA | F10: Prélèvements génitaux : vaginal, urétral, anal | G10: Ecouvillonnage pour examens microbiologiques | L10: Viskali Microbiologie : Prélèvements effectués à l'unité de prélèvement (UP) (GEDI 3706) | M10: extension demandée en novembre 2024 | N10: BM PP01 | O10: NA | P10: NA | Q10: =CONCATENATE(N10," _ ",O10," _ ",G10," _ ",H10," _ ",I10," _ ",J10," _ ",K10) -> BM PP01 _ NA _ Ecouvillonnage pour examens microbiologiques _ _ _ _
A11: HOPITAL CHARLES NICOLLE CHU ROUEN | B11: Biologie de la reproduction | C11: Biologie Médicale | D11: NA | E11: NA | F11: Sperme | G11: Recueil de sperme | L11: Viskali Procédure de recueil du sperme (GEDI 4106) | M11: extension demandée en novembre 2024 | N11: BM PP01 | O11: NA | P11: NA | Q11: =CONCATENATE(N11," _ ",O11," _ ",G11," _ ",H11," _ ",I11," _ ",J11," _ ",K11) -> BM PP01 _ NA _ Recueil de sperme _ _ _ _
A12: HOPITAL CHARLES NICOLLE CHU ROUEN | B12: Biologie de la reproduction | C12: Biologie Médicale | D12: NA | E12: NA | F12: Prélèvements gynécologiques | G12: Frottis cervico-vaginal | L12: Viskali Microbiologie : Prélèvements effectués à l'unité de prélèvement (UP) (GEDI 3706) | M12: extension demandée en novembre 2024 | N12: BM PP01 | O12: NA | P12: NA | Q12: =CONCATENATE(N12," _ ",O12," _ ",G12," _ ",H12," _ ",I12," _ ",J12," _ ",K12) -> BM PP01 _ NA _ Frottis cervico-vaginal _ _ _ _
A13: HOPITAL CHARLES NICOLLE CHU ROUEN | B13: Centres de prélèvement | C13: Biologie Médicale | D13: NA | E13: NA | F13: Nasopharyngés Oropharyngés | G13: Ecouvillonnage pour examens microbiologiques | L13: Viskali Microbiologie : Prélèvements effectués à l'unité de prélèvement (UP) (GEDI 3706) | M13: extension demandée en novembre 2024 | N13: BM PP01 | O13: NA | P13: NA | Q13: =CONCATENATE(N13," _ ",O13," _ ",G13," _ ",H13," _ ",I13," _ ",J13," _ ",K13) -> BM PP01 _ NA _ Ecouvillonnage pour examens microbiologiques _ _ _ _
A14: HOPITAL CHARLES NICOLLE CHU ROUEN | B14: Centres de prélèvement | C14: Biologie Médicale | D14: NA | E14: NA | F14: Peau Phanères Tissus cellulaires sous-cutanés | G14: Prélèvement cutané pour examens microbiologiques Prélèvement des phanères pour examens microbiologiques | L14: Viskali Procédure opératoire de la recherche de sarcopte (gale) (GEDI 1212) Prélèvements effectués à l'unité de prélèvement en parasitologie-mycologie 42147 | M14: extension demandée en novembre 2024 | N14: BM PP01 | O14: NA | P14: NA | Q14: =CONCATENATE(N14," _ ",O14," _ ",G14," _ ",H14," _ ",I14," _ ",J14," _ ",K14) -> BM PP01 _ NA _ Prélèvement cutané pour examens microbiologiques Prélèvement des phanères pour examens microbiologiques _ _ _ _
A15: HOPITAL CHARLES NICOLLE CHU ROUEN | B15: Consultation hématologie Services de soins | C15: Biologie Médicale | D15: NA | E15: NA | F15: Moelle osseuse | G15: Ponction sternale ou iliaque | L15: Viskali Protocole de prélèvement du myélogramme GEDI 1768 | M15: extension demandée en novembre 2024 | N15: BM PP01 | O15: NA | P15: NA | Q15: =CONCATENATE(N15," _ ",O15," _ ",G15," _ ",H15," _ ",I15," _ ",J15," _ ",K15) -> BM PP01 _ NA _ Ponction sternale ou iliaque _ _ _ _

Sheet Extensions demandées 2025
A1: Pôle B2P CHU de Rouen (8-3081) | C1: Liste détaillée des examens/analyses demandés à l'accréditation (réf 15081)
A2: Lieu de réalisation des opérations techniques (site) | B2: Service | C2: Domaine | D2: Sous-Famille | E2: Examen / analyse | F2: Nature de l'échantillon biologique (sang et dérivés, urine, selles, …) | G2: Principe de la méthode (préciser l'identification de l'équipement si méthode automatisée et le nombre ou préciser méthode manuelle, ainsi que la technique mise en oeuvre) | L2: Référence de la méthode (référence du document et version) | M2: Remarque(ajout, changement automate, changement de méthode, changement de réactif,…) | N2: Lignes de portée | O2: portée A/B | P2: Nombre actes réalisés en 2024
A3: HOPITAL CHARLES NICOLLE CHU ROUEN | B3: Virologie | C3: Biologie Médicale | D3: Microbiologie Générale (MICROBIOBM) | E3: Séquençage NGS de résistance VIH | F3: plasma, sang total EDTA | G3: Séquençage à Haut débit et Traitement bioinformatique | H3: Qualitatif | I3: Automatisée | J3: 1 | K3: MiSeq Illumina | L3: 42326 v1 | N3: BM MG06 | O3: B | P3: 117 (à partir d'aout 24) | Q3: =CONCATENATE(N3," _ ",O3," _ ",G3," _ ",H3," _ ",I3," _ ",J3," _ ",K3) -> BM MG06 _ B _ Séquençage à Haut débit et Traitement bioinformatique _ Qualitatif _ Automatisée _ 1 _ MiSeq Illumina
A4: HOPITAL CHARLES NICOLLE CHU ROUEN | B4: Hématologie | C4: Biologie Médicale | D4: Hématocytologie (HEMATOBM) | E4: Détermination de l'hématocrite par centrifugation | F4: Sang total EDTA | G4: Détermination de l'hématocrite par centrifugation avec des tubes capillaires auto-étanchéifiables | H4: Quantitatif | I4: manuelle | L4: 31151 v1 | N4: BM HB03 | O4: A | P4: 48 | Q4: =CONCATENATE(N4," _ ",O4," _ ",G4," _ ",H4," _ ",I4," _ ",J4," _ ",K4) -> BM HB03 _ A _ Détermination de l'hématocrite par centrifugation avec des tubes capillaires auto-étanchéifiables _ Quantitatif _ manuelle _ _
A5: CENTRE HOSPITALIER SAINT JULIEN | B5: Virologie | C5: Biologie Médicale | D5: Virologie Spécialisée (VIROH) | E5: PCR Grippe VRS SARS-CoV-2 | F5: écouvillons naso-pharyngés en milieu de transport viral | G5: Détection d'acides nucléiques avec ou sans amplification, après extraction et purification (hybridation, PCR, …) – Biologie moléculaire | H5: Qualitatif | I5: Automatisée | J5: 3 | K5: Cepheid, GeneXpert | L5: 36105 v3 | N5: BM VB01 | O5: A | P5: 716 | Q5: =CONCATENATE(N5," _ ",O5," _ ",G5," _ ",H5," _ ",I5," _ ",J5," _ ",K5) -> BM VB01 _ A _ Détection d'acides nucléiques avec ou sans amplification, après extraction et purification (hybridation, PCR, …) – Biologie moléculaire _ Qualitatif _ Automatisée _ 3 _ Cepheid, GeneXpert
Q6: =CONCATENATE(N6," _ ",O6," _ ",G6," _ ",H6," _ ",I6," _ ",J6," _ ",K6) -> _ _ _ _ _ _
Q7: =CONCATENATE(N7," _ ",O7," _ ",G7," _ ",H7," _ ",I7," _ ",J7," _ ",K7) -> _ _ _ _ _ _
Q8: =CONCATENATE(N8," _ ",O8," _ ",G8," _ ",H8," _ ",I8," _ ",J8," _ ",K8) -> _ _ _ _ _ _
Q9: =CONCATENATE(N9," _ ",O9," _ ",G9," _ ",H9," _ ",I9," _ ",J9," _ ",K9) -> _ _ _ _ _ _
Q10: =CONCATENATE(N10," _ ",O10," _ ",G10," _ ",H10," _ ",I10," _ ",J10," _ ",K10) -> _ _ _ _ _ _
Q11: =CONCATENATE(N11," _ ",O11," _ ",G11," _ ",H11," _ ",I11," _ ",J11," _ ",K11) -> _ _ _ _ _ _
Q12: =CONCATENATE(N12," _ ",O12," _ ",G12," _ ",H12," _ ",I12," _ ",J12," _ ",K12) -> _ _ _ _ _ _
Q13: =CONCATENATE(N13," _ ",O13," _ ",G13," _ ",H13," _ ",I13," _ ",J13," _ ",K13) -> _ _ _ _ _ _

Sheet FLEXI+
A1: Site | B1: Lieu de réalisation des opérations | C1: Examen / analyse | D1: Nature de l'échantillon biologique/de la région anatomique | E1: Principe de la méthode | F1: Référence de la méthode | G1: Nature de l'évolution (ajout, changement affectant les performances de la méthode, ...) et Remarque
A2: ='Examens accrédités et ajouts'!A15 -> HOPITAL CHARLES NICOLLE CHU ROUEN | B2: ='Examens accrédités et ajouts'!B15 -> Biochimie Générale | C2: ='Examens accrédités et ajouts'!E15 -> Créatine kinase | D2: ='Examens accrédités et ajouts'!F15 -> Sang | E2: ='Examens accrédités et ajouts'!Q15 -> BM BB01 _ A _ Cinétique enzymatique standardisée IFCC _ Quantitatif _ Automatisée _ 1 _ Cobas Pro Roche | F2: ='Examens accrédités et ajouts'!L15 -> 10608 v4 | G2: ='Examens accrédités et ajouts'!M15 -> Changement automate: mise en production le 25/9/24
A3: ='Examens accrédités et ajouts'!A16 -> HOPITAL CHARLES NICOLLE CHU ROUEN | B3: ='Examens accrédités et ajouts'!B16 -> Biochimie Générale | C3: ='Examens accrédités et ajouts'!E16 -> Potassium | D3: ='Examens accrédités et ajouts'!F16 -> Sang | E3: ='Examens accrédités et ajouts'!Q16 -> BM BB01 _ A _ Potentiométrie indirecte _ Quantitatif _ Automatisée _ 3 _ Cobas Pro Roche | F3: ='Examens accrédités et ajouts'!L16 -> 10674 v6 | G3: ='Examens accrédités et ajouts'!M16 -> Changement automate: mise en production le 25/9/24 et 16/12/2024
A4: ='Examens accrédités et ajouts'!A17 -> HOPITAL CHARLES NICOLLE CHU ROUEN | B4: ='Examens accrédités et ajouts'!B17 -> Biochimie Générale | C4: ='Examens accrédités et ajouts'!E17 -> Troponine T | D4: ='Examens accrédités et ajouts'!F17 -> Sang | E4: ='Examens accrédités et ajouts'!Q17 -> BM BB01 _ A _ Electrochimiluminescence _ Quantitatif _ Automatisée _ 3 _ Cobas Pro Roche | F4: ='Examens accrédités et ajouts'!L17 -> 10673 v6 | G4: ='Examens accrédités et ajouts'!M17 -> Changement automate: mise en production le 25/9/24 et 16/12/2024
A5: ='Examens accrédités et ajouts'!A18 -> HOPITAL CHARLES NICOLLE CHU ROUEN | B5: ='Examens accrédités et ajouts'!B18 -> Biochimie Générale | C5: ='Examens accrédités et ajouts'!E18 -> Phosphatases alcalines | D5: ='Examens accrédités et ajouts'!F18 -> Sang | E5: ='Examens accrédités et ajouts'!Q18 -> BM BB01 _ A _ Colorimétrie enzymatique _ Quantitatif _ Automatisée _ 3 _ Cobas Pro Roche | F5: ='Examens accrédités et ajouts'!L18 -> 14978 v004 | G5: ='Examens accrédités et ajouts'!M18 -> Changement automate: mise en production le 25/9/24 et 16/12/2024
A6: ='Examens accrédités et ajouts'!A19 -> HOPITAL CHARLES NICOLLE CHU ROUEN | B6: ='Examens accrédités et ajouts'!B19 -> Biochimie Générale | C6: ='Examens accrédités et ajouts'!E19 -> Magnésium | D6: ='Examens accrédités et ajouts'!F19 -> Sang | E6: ='Examens accrédités et ajouts'!Q19 -> BM BB01 _ A _ Colorimétrie _ Quantitatif _ Automatisée _ 2 _ Cobas Pro Roche | F6: ='Examens accrédités et ajouts'!L19 -> 15040 v005 | G6: ='Examens accrédités et ajouts'!M19 -> Changement automate: mise en production le 25/9/24 et 16/12/2024
A7: ='Examens accrédités et ajouts'!A20 -> HOPITAL CHARLES NICOLLE CHU ROUEN | B7: ='Examens accrédités et ajouts'!B20 -> Biochimie Générale | C7: ='Examens accrédités et ajouts'!E20 -> Chlore | D7: ='Examens accrédités et ajouts'!F20 -> Sang | E7: ='Examens accrédités et ajouts'!Q20 -> BM BB01 _ A _ Potentiométrie indirecte _ Quantitatif _ Automatisée _ 3 _ Cobas Pro Roche | F7: ='Examens accrédités et ajouts'!L20 -> 15038 v006 | G7: ='Examens accrédités et ajouts'!M20 -> Changement automate: mise en production le 25/9/24 et 16/12/2024
A8: ='Examens accrédités et ajouts'!A21 -> HOPITAL CHARLES NICOLLE CHU ROUEN | B8: ='Examens accrédités et ajouts'!B21 -> Biochimie Générale | C8: ='Examens accrédités et ajouts'!E21 -> Lipase | D8: ='Examens accrédités et ajouts'!F21 -> Sang | E8: ='Examens accrédités et ajouts'!Q21 -> BM BB01 _ A _ Colorimétrie enzymatique _ Quantitatif _ Automatisée _ 2 _ Cobas Pro Roche | F8: ='Examens accrédités et ajouts'!L21 -> 15039 v008 | G8: ='Examens accrédités et ajouts'!M21 -> Changement automate: mise en production le 25/9/24 et 16/12/2024
A9: ='Examens accrédités et ajouts'!A22 -> HOPITAL CHARLES NICOLLE CHU ROUEN | B9: ='Examens accrédités et ajouts'!B22 -> Biochimie Générale | C9: ='Examens accrédités et ajouts'!E22 -> Calcium | D9: ='Examens accrédités et ajouts'!F22 -> Sang | E9: ='Examens accrédités et ajouts'!Q22 -> BM BB01 _ A _ Colorimétrie _ Quantitatif _ Automatisée _ 3 _ Cobas Pro Roche | F9: ='Examens accrédités et ajouts'!L22 -> 15026 v005 | G9: ='Examens accrédités et ajouts'!M22 -> Changement automate: mise en production le 25/9/24 et 16/12/2024
A10: ='Examens accrédités et ajouts'!A23 -> HOPITAL CHARLES NICOLLE CHU ROUEN | B10: ='Examens accrédités et ajouts'!B23 -> Biochimie Générale | C10: ='Examens accrédités et ajouts'!E23 -> Urée | D10: ='Examens accrédités et ajouts'!F23 -> Sang | E10: ='Examens accrédités et ajouts'!Q23 -> BM BB01 _ A _ Méthode enzymatique (Uréase) _ Quantitatif _ Automatisée _ 3 _ Cobas Pro Roche | F10: ='Examens accrédités et ajouts'!L23 -> 15075 v006 | G10: ='Examens accrédités et ajouts'!M23 -> Changement automate: mise en production le 25/9/24 et 16/12/2024
A11: ='Examens accrédités et ajouts'!A24 -> HOPITAL CHARLES NICOLLE CHU ROUEN | B11: ='Examens accrédités et ajouts'!B24 -> Biochimie Générale | C11: ='Examens accrédités et ajouts'!E24 -> Thyréostimuline | D11: ='Examens accrédités et ajouts'!F24 -> Sang | E11: ='Examens accrédités et ajouts'!Q24 -> BM BB01 _ A _ Electrochimiluminescence _ Quantitatif _ Automatisée _ 2 _ Cobas pro Roche | F11: ='Examens accrédités et ajouts'!L24 -> 15073 v003 | G11: ='Examens accrédités et ajouts'!M24 -> Changement automate: mise en production le 25/9/24
A12: ='Examens accrédités et ajouts'!A25 -> HOPITAL CHARLES NICOLLE CHU ROUEN | B12: ='Examens accrédités et ajouts'!B25 -> Biochimie Générale | C12: ='Examens accrédités et ajouts'!E25 -> Sodium | D12: ='Examens accrédités et ajouts'!F25 -> Sang | E12: ='Examens accrédités et ajouts'!Q25 -> BM BB01 _ A _ Potentiométrie indirecte _ Quantitatif _ Automatisée _ 3 _ Cobas Pro Roche | F12: ='Examens accrédités et ajouts'!L25 -> 15067 v006 | G12: ='Examens accrédités et ajouts'!M25 -> Changement automate: mise en production le 25/9/24 et 16/12/2024
A13: ='Examens accrédités et ajouts'!A26 -> HOPITAL CHARLES NICOLLE CHU ROUEN | B13: ='Examens accrédités et ajouts'!B26 -> Biochimie Générale | C13: ='Examens accrédités et ajouts'!E26 -> Protides | D13: ='Examens accrédités et ajouts'!F26 -> Sang | E13: ='Examens accrédités et ajouts'!Q26 -> BM BB01 _ A _ Colorimétrique (Biuret) _ Quantitatif _ Automatisée _ 3 _ Cobas Pro Roche | F13: ='Examens accrédités et ajouts'!L26 -> 15030 v007 | G13: ='Examens accrédités et ajouts'!M26 -> Changement automate: mise en production le 25/9/24 et 16/12/2024
... A617: ='Examens accrédités et ajouts'!A630 -> 0 | B617: ='Examens accrédités et ajouts'!B630 -> 0 | C617: ='Examens accrédités et ajouts'!E630 -> 0 | D617: ='Examens accrédités et ajouts'!F630 -> 0 | E617: ='Examens accrédités et ajouts'!Q630 -> _ _ _ _ _ _ | F617: ='Examens accrédités et ajouts'!L630 -> 0 | G617: ='Examens accrédités et ajouts'!M630 -> 0
A618: ='Examens accrédités et ajouts'!A630 -> 0 | B618: ='Examens accrédités et ajouts'!B630 -> 0 | C618: ='Examens accrédités et ajouts'!E630 -> 0 | D618: ='Examens accrédités et ajouts'!F630 -> 0 | E618: ='Examens accrédités et ajouts'!Q630 -> _ _ _ _ _ _ | F618: ='Examens accrédités et ajouts'!L630 -> 0 | G618: ='Examens accrédités et ajouts'!M630 -> 0
A619: ='Examens accrédités et ajouts'!A631 -> 0 | B619: ='Examens accrédités et ajouts'!B631 -> 0 | C619: ='Examens accrédités et ajouts'!E631 -> 0 | D619: ='Examens accrédités et ajouts'!F631 -> 0 | E619: ='Examens accrédités et ajouts'!Q631 -> _ _ _ _ _ _ | F619: ='Examens accrédités et ajouts'!L631 -> 0 | G619: ='Examens accrédités et ajouts'!M631 -> 0
A620: ='Examens accrédités et ajouts'!A632 -> 0 | B620: ='Examens accrédités et ajouts'!B632 -> 0 | C620: ='Examens accrédités et ajouts'!E632 -> 0 | D620: ='Examens accrédités et ajouts'!F632 -> 0 | E620: ='Examens accrédités et ajouts'!Q632 -> 0 | F620: ='Examens accrédités et ajouts'!L632 -> 0 | G620: ='Examens accrédités et ajouts'!M632 -> 0
A621: ='Examens accrédités et ajouts'!A633 -> 0 | B621: ='Examens accrédités et ajouts'!B633 -> 0 | C621: ='Examens accrédités et ajouts'!E633 -> 0 | D621: ='Examens accrédités et ajouts'!F633 -> 0 | E621: ='Examens accrédités et ajouts'!Q633 -> 0 | F621: ='Examens accrédités et ajouts'!L633 -> 0 | G621: ='Examens accrédités et ajouts'!M633 -> 0
A622: ='Examens accrédités et ajouts'!A634 -> 0 | B622: ='Examens accrédités et ajouts'!B634 -> 0 | C622: ='Examens accrédités et ajouts'!E634 -> 0 | D622: ='Examens accrédités et ajouts'!F634 -> 0 | E622: ='Examens accrédités et ajouts'!Q634 -> 0 | F622: ='Examens accrédités et ajouts'!L634 -> 0 | G622: ='Examens accrédités et ajouts'!M634 -> 0
A623: ='Examens accrédités et ajouts'!A635 -> 0 | B623: ='Examens accrédités et ajouts'!B635 -> 0 | C623: ='Examens accrédités et ajouts'!E635 -> 0 | D623: ='Examens accrédités et ajouts'!F635 -> 0 | E623: ='Examens accrédités et ajouts'!Q635 -> 0 | F623: ='Examens accrédités et ajouts'!L635 -> 0 | G623: ='Examens accrédités et ajouts'!M635 -> 0
A624: ='Examens accrédités et ajouts'!A636 -> 0 | B624: ='Examens accrédités et ajouts'!B636 -> 0 | C624: ='Examens accrédités et ajouts'!E636 -> 0 | D624: ='Examens accrédités et ajouts'!F636 -> 0 | E624: ='Examens accrédités et ajouts'!Q636 -> % activité _ _ _ _ _ _ | F624: ='Examens accrédités et ajouts'!L636 -> 0 | G624: ='Examens accrédités et ajouts'!M636 -> 0
A625: ='Examens accrédités et ajouts'!A637 -> 0 | B625: ='Examens accrédités et ajouts'!B637 -> 0 | C625: ='Examens accrédités et ajouts'!E637 -> 0 | D625: ='Examens accrédités et ajouts'!F637 -> 0 | E625: ='Examens accrédités et ajouts'!Q637 -> 0 | F625: ='Examens accrédités et ajouts'!L637 -> 0 | G625: ='Examens accrédités et ajouts'!M637 -> 0
A626: ='Examens accrédités et ajouts'!A638 -> HOPITAL CHARLES NICOLLE CHU ROUEN | B626: ='Examens accrédités et ajouts'!B638 -> Centres de prélèvement | C626: ='Examens accrédités et ajouts'!E638 -> NA | D626: ='Examens accrédités et ajouts'!F638 -> Peau Phanères Tissus cellulaires sous-cutanés | E626: ='Examens accrédités et ajouts'!Q638 -> BM PP01 _ NA _ Prélèvement cutané pour examens microbiologiques Prélèvement des phanères pour examens microbiologiques _ _ _ _ | F626: ='Examens accrédités et ajouts'!L638 -> Viskali Procédure opératoire de la recherche de sarcopte (gale) (GEDI 1212) MO prélèvement mycologique | G626: ='Examens accrédités et ajouts'!M638 -> extension demandée en novembre 2024
A627: ='Examens accrédités et ajouts'!A639 -> HOPITAL CHARLES NICOLLE CHU ROUEN | B627: ='Examens accrédités et ajouts'!B639 -> Consultation hématologie Services de soins | C627: ='Examens accrédités et ajouts'!E639 -> NA | D627: ='Examens accrédités et ajouts'!F639 -> Moelle osseuse | E627: ='Examens accrédités et ajouts'!Q639 -> BM PP01 _ NA _ Ponction sternale ou iliaque _ _ _ _ | F627: ='Examens accrédités et ajouts'!L639 -> Viskali Protocole de prélèvement du myélogramme GEDI 1768 | G627: ='Examens accrédités et ajouts'!M639 -> extension demandée en novembre 2024
A628: ='Examens accrédités et ajouts'!A640 -> 0 | B628: ='Examens accrédités et ajouts'!B640 -> 0 | C628: ='Examens accrédités et ajouts'!E640 -> 0 | D628: ='Examens accrédités et ajouts'!F640 -> 0 | E628: ='Examens accrédités et ajouts'!Q640 -> 0 | F628: ='Examens accrédités et ajouts'!L640 -> 0 | G628: ='Examens accrédités et ajouts'!M640 -> 0
A629: ='Examens accrédités et ajouts'!A641 -> 0 | B629: ='Examens accrédités et ajouts'!B641 -> 0 | C629: ='Examens accrédités et ajouts'!E641 -> 0 | D629: ='Examens accrédités et ajouts'!F641 -> 0 | E629: ='Examens accrédités et ajouts'!Q641 -> 0 | F629: ='Examens accrédités et ajouts'!L641 -> 0 | G629: ='Examens accrédités et ajouts'!M641 -> 0
... A687: ='Examens accrédités et ajouts'!A699 -> 0 | B687: ='Examens accrédités et ajouts'!B699 -> 0 | C687: ='Examens accrédités et ajouts'!E699 -> 0 | D687: ='Examens accrédités et ajouts'!F699 -> 0 | E687: ='Examens accrédités et ajouts'!Q699 -> 0 | F687: ='Examens accrédités et ajouts'!L699 -> 0 | G687: ='Examens accrédités et ajouts'!M699 -> 0
A688: ='Examens accrédités et ajouts'!A698 -> 0 | B688: ='Examens accrédités et ajouts'!B698 -> 0 | C688: ='Examens accrédités et ajouts'!E698 -> 0 | D688: ='Examens accrédités et ajouts'!F698 -> 0 | E688: ='Examens accrédités et ajouts'!Q698 -> 0 | F688: ='Examens accrédités et ajouts'!L698 -> 0 | G688: ='Examens accrédités et ajouts'!M698 -> 0
A689: ='Examens accrédités et ajouts'!A699 -> 0 | B689: ='Examens accrédités et ajouts'!B699 -> 0 | C689: ='Examens accrédités et ajouts'!E699 -> 0 | D689: ='Examens accrédités et ajouts'!F699 -> 0 | E689: ='Examens accrédités et ajouts'!Q699 -> 0 | F689: ='Examens accrédités et ajouts'!L699 -> 0 | G689: ='Examens accrédités et ajouts'!M699 -> 0
A690: ='Examens accrédités et ajouts'!A700 -> 0 | B690: ='Examens accrédités et ajouts'!B700 -> 0 | C690: ='Examens accrédités et ajouts'!E700 -> 0 | D690: ='Examens accrédités et ajouts'!F700 -> 0 | E690: ='Examens accrédités et ajouts'!Q700 -> 0 | F690: ='Examens accrédités et ajouts'!L700 -> 0 | G690: ='Examens accrédités et ajouts'!M700 -> 0
A691: ='Examens accrédités et ajouts'!A701 -> 0 | B691: ='Examens accrédités et ajouts'!B701 -> 0 | C691: ='Examens accrédités et ajouts'!E701 -> 0 | D691: ='Examens accrédités et ajouts'!F701 -> 0 | E691: ='Examens accrédités et ajouts'!Q701 -> 0 | F691: ='Examens accrédités et ajouts'!L701 -> 0 | G691: ='Examens accrédités et ajouts'!M701 -> 0
A692: ='Examens accrédités et ajouts'!A702 -> 0 | B692: ='Examens accrédités et ajouts'!B702 -> 0 | C692: ='Examens accrédités et ajouts'!E702 -> 0 | D692: ='Examens accrédités et ajouts'!F702 -> 0 | E692: ='Examens accrédités et ajouts'!Q702 -> 0 | F692: ='Examens accrédités et ajouts'!L702 -> 0 | G692: ='Examens accrédités et ajouts'!M702 -> 0
A693: ='Examens accrédités et ajouts'!A703 -> 0 | B693: ='Examens accrédités et ajouts'!B703 -> 0 | C693: ='Examens accrédités et ajouts'!E703 -> 0 | D693: ='Examens accrédités et ajouts'!F703 -> 0 | E693: ='Examens accrédités et ajouts'!Q703 -> 0 | F693: ='Examens accrédités et ajouts'!L703 -> 0 | G693: ='Examens accrédités et ajouts'!M703 -> 0
A694: ='Examens accrédités et ajouts'!A704 -> 0 | B694: ='Examens accrédités et ajouts'!B704 -> 0 | C694: ='Examens accrédités et ajouts'!E704 -> 0 | D694: ='Examens accrédités et ajouts'!F704 -> 0 | E694: ='Examens accrédités et ajouts'!Q704 -> 0 | F694: ='Examens accrédités et ajouts'!L704 -> 0 | G694: ='Examens accrédités et ajouts'!M704 -> 0
A695: ='Examens accrédités et ajouts'!A705 -> 0 | B695: ='Examens accrédités et ajouts'!B705 -> 0 | C695: ='Examens accrédités et ajouts'!E705 -> 0 | D695: ='Examens accrédités et ajouts'!F705 -> 0 | E695: ='Examens accrédités et ajouts'!Q705 -> 0 | F695: ='Examens accrédités et ajouts'!L705 -> 0 | G695: ='Examens accrédités et ajouts'!M705 -> 0
A696: ='Examens accrédités et ajouts'!A706 -> 0 | B696: ='Examens accrédités et ajouts'!B706 -> 0 | C696: ='Examens accrédités et ajouts'!E706 -> 0 | D696: ='Examens accrédités et ajouts'!F706 -> 0 | E696: ='Examens accrédités et ajouts'!Q706 -> 0 | F696: ='Examens accrédités et ajouts'!L706 -> 0 | G696: ='Examens accrédités et ajouts'!M706 -> 0
A697: ='Examens accrédités et ajouts'!A707 -> 0 | B697: ='Examens accrédités et ajouts'!B707 -> 0 | C697: ='Examens accrédités et ajouts'!E707 -> 0 | D697: ='Examens accrédités et ajouts'!F707 -> 0 | E697: ='Examens accrédités et ajouts'!Q707 -> 0 | F697: ='Examens accrédités et ajouts'!L707 -> 0 | G697: ='Examens accrédités et ajouts'!M707 -> 0
A698: ='Examens accrédités et ajouts'!A708 -> 0 | B698: ='Examens accrédités et ajouts'!B708 -> 0 | C698: ='Examens accrédités et ajouts'!E708 -> 0 | D698: ='Examens accrédités et ajouts'!F708 -> 0 | E698: ='Examens accrédités et ajouts'!Q708 -> 0 | F698: ='Examens accrédités et ajouts'!L708 -> 0 | G698: ='Examens accrédités et ajouts'!M708 -> 0
A699: ='Examens accrédités et ajouts'!A709 -> 0 | B699: ='Examens accrédités et ajouts'!B709 -> 0 | C699: ='Examens accrédités et ajouts'!E709 -> 0 | D699: ='Examens accrédités et ajouts'!F709 -> 0 | E699: ='Examens accrédités et ajouts'!Q709 -> 0 | F699: ='Examens accrédités et ajouts'!L709 -> 0 | G699: ='Examens accrédités et ajouts'!M709 -> 0
... A764: ='Examens accrédités et ajouts'!A774 -> 0 | B764: ='Examens accrédités et ajouts'!B774 -> 0 | C764: ='Examens accrédités et ajouts'!E774 -> 0 | D764: ='Examens accrédités et ajouts'!F774 -> 0 | E764: ='Examens accrédités et ajouts'!Q774 -> 0 | F764: ='Examens accrédités et ajouts'!L774 -> 0 | G764: ='Examens accrédités et ajouts'!M774 -> 0
...

Sheet EBMD
A1: Site | B1: Site EBMD | C1: Lieu de réalisation des opérations | D1: Examen / analyse | E1: Nature de l'échantillon biologique/de la région anatomique | F1: Principe de la méthode | G1: Référence de la méthode | H1: Nature de l'évolution (ajout, changement affectant les performances de la méthode, ...) et Remarque | I1: Flexi
A2: HOPITAL CHARLES NICOLLE CHU ROUEN | B2: HOPITAL CHARLES NICOLLE CHU ROUEN | C2: Site Charles Nicolle Fédération cœur Thorax Vaisseaux Anesthésiologie/UF 2172 | D2: pH (Gaz du sang) | E2: Sang total artériel et veineux | F2: BM BB06 _ A _ Potentiométrie directe _ Quantitatif _ Automatisée _ 1 _ GEM Premier 5000 N° série: 24067194 N° BIO: 24X125 | G2: 42402 V1 | H2: Janvier 2025 Changement d'automate Changement de direction des BLOCS Opératoires => Fédération cœur Thorax Vaisseaux | I2: OK
A3: HOPITAL CHARLES NICOLLE CHU ROUEN | B3: HOPITAL CHARLES NICOLLE CHU ROUEN | C3: Site Charles Nicolle Fédération cœur Thorax Vaisseaux Anesthésiologie/UF 2172 | D3: pCO2 (Gaz du sang) | E3: Sang total artériel et veineux | F3: BM BB06 _ A _ Potentiométrie _ Quantitatif _ Automatisée _ 1 _ GEM Premier 5000 N° série: 24067194 N° BIO: 24X125 | G3: 42402 V1 | H3: Janvier 2025 Changement d'automate Changement de direction des BLOCS Opératoires => Fédération cœur Thorax Vaisseaux | I3: OK
A4: HOPITAL CHARLES NICOLLE CHU ROUEN | B4: HOPITAL CHARLES NICOLLE CHU ROUEN | C4: Site Charles Nicolle Fédération cœur Thorax Vaisseaux Anesthésiologie/UF 2172 | D4: Sodium (Gaz du sang) | E4: Sang total artériel, capillaire, veineux, artério-veineux | F4: BM BB06 _ A _ Potentiométrie directe _ Quantitatif _ Automatisée _ 1 _ GEM Premier 5000 N° série: 24067194 N° BIO: 24X125 | G4: 42402 V1 | H4: Janvier 2025 Changement d'automate Changement de direction des BLOCS Opératoires => Fédération cœur Thorax Vaisseaux | I4: OK
A5: HOPITAL CHARLES NICOLLE CHU ROUEN | B5: HOPITAL CHARLES NICOLLE CHU ROUEN | C5: Site Charles Nicolle Fédération cœur Thorax Vaisseaux Anesthésiologie/UF 2172 | D5: Potassium (Gaz du sang) | E5: Sang total artériel, capillaire, veineux, artério-veineux | F5: BM BB06 _ A _ Potentiométrie directe _ Quantitatif _ Automatisée _ 1 _ GEM Premier 5000 N° série: 24067194 N° BIO: 24X125 | G5: 42402 V1 | H5: Janvier 2025 Changement d'automate Changement de direction des BLOCS Opératoires => Fédération cœur Thorax Vaisseaux | I5: OK
A6: HOPITAL CHARLES NICOLLE CHU ROUEN | B6: HOPITAL CHARLES NICOLLE CHU ROUEN | C6: Site Charles Nicolle Fédération cœur Thorax Vaisseaux Anesthésiologie/UF 2172 | D6: Lactate (Gaz du sang) | E6: Sang total artériel, capillaire, veineux, artério-veineux | F6: BM BB06 _ A _ Ampérométrie _ Quantitatif _ Automatisée _ 1 _ GEM Premier 5000 N° série: 24067194 N° BIO: 24X125 | G6: 42402 V1 | H6: Janvier 2025 Changement d'automate Changement de direction des BLOCS Opératoires => Fédération cœur Thorax Vaisseaux | I6: OK
A7: HOPITAL CHARLES NICOLLE CHU ROUEN | B7: HOPITAL CHARLES NICOLLE CHU ROUEN | C7: Site Charles Nicolle Fédération cœur Thorax Vaisseaux Anesthésiologie/UF 2172 | D7: PO2 (Gaz du sang) | E7: Sang total artériel, capillaire, veineux, artério-veineux | F7: BM BB06 _ A _ Ampérométrie _ Quantitatif _ Automatisée _ 1 _ GEM Premier 5000 N° série: 24067194 N° BIO: 24X125 | G7: 42402 V1 | H7: Janvier 2025 Changement d'automate Changement de direction des BLOCS Opératoires => Fédération cœur Thorax Vaisseaux | I7: OK
A8: HOPITAL CHARLES NICOLLE CHU ROUEN | B8: HOPITAL CHARLES NICOLLE CHU ROUEN | C8: Site Charles Nicolle Fédération cœur Thorax Vaisseaux Anesthésiologie/UF 2172 | D8: Glucose (Gaz du sang) | E8: Sang total artériel, capillaire, veineux, artério-veineux | F8: BM BB06 _ A _ Ampérométrie _ Quantitatif _ Automatisée _ 1 _ GEM Premier 5000 N° série: 24067194 N° BIO: 24X125 | G8: 42402 V1 | H8: Janvier 2025 Changement d'automate Changement de direction des BLOCS Opératoires => Fédération cœur Thorax Vaisseaux | I8: OK
A9: HOPITAL CHARLES NICOLLE CHU ROUEN | B9: HOPITAL CHARLES NICOLLE CHU ROUEN | C9: Site Charles Nicolle Fédération cœur Thorax Vaisseaux Anesthésiologie/UF 2172 | D9: Hémoglobine totale (Gaz du sang) | E9: Sang total artériel, capillaire, veineux, artério-veineux | F9: BM BB06 _ A _ CO-Oxymétrie _ Quantitatif _ Automatisée _ 1 _ GEM Premier 5000 N° série: 24067194 N° BIO: 24X125 | G9: 42402 V1 | H9: Janvier 2025 Changement d'automate Changement de direction des BLOCS Opératoires => Fédération cœur Thorax Vaisseaux | I9: OK
A10: HOPITAL CHARLES NICOLLE CHU ROUEN | B10: HOPITAL CHARLES NICOLLE CHU ROUEN | C10: Site Charles Nicolle Pole FME Réanimation pédiatrique/UF 5661 | D10: pH (Gaz du sang) | E10: Sang total artériel et veineux | F10: BM BB06 _ A _ Potentiométrie directe _ Quantitatif _ Automatisée _ 1 _ GEM Premier 5000 N° série: 24087614 N° BIO: 24X128 | G10: 42386 V1 | H10: Ajout dans la portée d'accréditation | I10: OK
A11: HOPITAL CHARLES NICOLLE CHU ROUEN | B11: HOPITAL CHARLES NICOLLE CHU ROUEN | C11: Site Charles Nicolle Pole FME Réanimation pédiatrique/UF 5661 | D11: pCO2 (Gaz du sang) | E11: Sang total artériel et veineux | F11: BM BB06 _ A _ Potentiométrie _ Quantitatif _ Automatisée _ 1 _ GEM Premier 5000 N° série: 24087614 N° BIO: 24X128 | G11: 42386 V1 | H11: Ajout dans la portée d'accréditation | I11: OK
A12: HOPITAL CHARLES NICOLLE CHU ROUEN | B12: HOPITAL CHARLES NICOLLE CHU ROUEN | C12: Site Charles Nicolle Pole FME Réanimation pédiatrique/UF 5661 | D12: Sodium (Gaz du sang) | E12: Sang total artériel, capillaire, veineux, artério-veineux | F12: BM BB06 _ A _ Potentiométrie directe _ Quantitatif _ Automatisée _ 1 _ GEM Premier 5000 N° série: 24087614 N° BIO: 24X128 | G12: 42386 V1 | H12: Ajout dans la portée d'accréditation | I12: OK
... A41: HOPITAL CHARLES NICOLLE CHU ROUEN | B41: HOPITAL CHARLES NICOLLE CHU ROUEN | C41: Site Charles Nicolle Pole RAS Réanimation chirugicale et médecine / UF6280 | D41: Hémoglobine totale (Gaz du sang) | E41: Sang total artériel, capillaire, veineux, artério-veineux | F41: BM BB06 _ A _ CO-Oxymétrie _ Quantitatif _ Automatisée _ 1 _ GEM Premier 5000 N° série: 24087616 N° BIO: 24X126 | G41: 43608 V1 | H41: Ajout dans la portée d'accréditation | I41: OK
